<?xml version="1.0"?>
<robot xmlns:sensor="http://playerstage.sourceforge.net/gazebo/xmlschema/#sensor" xmlns:controller="http://playerstage.sourceforge.net/gazebo/xmlschema/#controller" xmlns:interface="http://playerstage.sourceforge.net/gazebo/xmlschema/#interface" xmlns:xacro="http://ros.org/wiki/xacro" name="oryxbot_arm">
  <!-- Defining the colors used in this robot -->
  <material name="Black">
    <color rgba="0 0 0 1"/>
  </material>
  <material name="White">
    <color rgba="1 1 1 1"/>
  </material>
  <material name="Grey">
    <color rgba="0.9 0.9 0.9 1"/>
  </material>
  <link name="base_link">
    <inertial>
      <origin xyz="0 0 0" rpy="0 0 0"/>
      <mass value="100"/>
      <inertia ixx="1" ixy="0" ixz="0" iyy="1" iyz="0" izz="1"/>
    </inertial>
    <visual>
      <origin xyz="0 0 0" rpy="0 0 0"/>
      <geometry>
        <mesh filename="package://oryxbot_description/meshes/arm/base_link.STL"/>
      </geometry>
      <material name="White"/>
    </visual>
    <collision>
      <origin xyz="0 0 0" rpy="0 0 0"/>
      <geometry>
        <mesh filename="package://oryxbot_description/meshes/arm/base_link.STL"/>
      </geometry>
    </collision>
  </link>
  <joint name="joint_1" type="revolute">
    <origin xyz="0 0 0.024" rpy="0 0 0"/>
    <parent link="base_link"/>
    <child link="link_1"/>
    <axis xyz="0 0 1"/>
    <limit effort="150.0" lower="-3.14159265" upper="3.14159265" velocity="3.15"/>
  </joint>
  <link name="link_1">
    <inertial>
      <origin xyz="0 0 0" rpy="0 0 0"/>
      <mass value="0.1"/>
      <inertia ixx="1" ixy="0" ixz="0" iyy="1" iyz="0" izz="1"/>
    </inertial>
    <visual>
      <origin xyz="0 0 0" rpy="0 0 0"/>
      <geometry>
        <mesh filename="package://oryxbot_description/meshes/arm/link_1.STL"/>
      </geometry>
      <!--material name="White"/-->
    </visual>
    <collision>
      <origin xyz="0 0 0" rpy="0 0 0"/>
      <geometry>
        <mesh filename="package://oryxbot_description/meshes/arm/link_1.STL"/>
      </geometry>
    </collision>
  </link>
  <joint name="joint_2" type="revolute">
    <origin xyz="-0.01175 0 0.114" rpy="1.570796325 0 -1.570796325"/>
    <parent link="link_1"/>
    <child link="link_2"/>
    <axis xyz="0 0 1"/>
    <limit effort="150.0" lower="0" upper="1.570796325" velocity="3.15"/>
  </joint>
  <link name="link_2">
    <inertial>
      <origin xyz="0 0 0" rpy="0 0 0"/>
      <mass value="0.1"/>
      <inertia ixx="1" ixy="0" ixz="0" iyy="1" iyz="0" izz="1"/>
    </inertial>
    <visual>
      <origin xyz="0 0 0" rpy="0 0 0"/>
      <geometry>
        <mesh filename="package://oryxbot_description/meshes/arm/link_2.STL"/>
      </geometry>
      <!--material name="Black"/-->
    </visual>
    <collision>
      <origin xyz="0 0 0" rpy="0 0 0"/>
      <geometry>
        <mesh filename="package://oryxbot_description/meshes/arm/link_2.STL"/>
      </geometry>
    </collision>
  </link>
  <joint name="joint_5" type="revolute">
    <origin xyz="0.02699 0.13228 -0.01175" rpy="0 3.14159265 0"/>
    <parent link="link_2"/>
    <child link="link_5"/>
    <axis xyz="0 0 1"/>
    <limit effort="150.0" lower="0" upper="1.570796325" velocity="3.15"/>
  </joint>
  <link name="link_5">
    <inertial>
      <origin xyz="0 0 0" rpy="0 0 0"/>
      <mass value="0.1"/>
      <inertia ixx="1" ixy="0" ixz="0" iyy="1" iyz="0" izz="1"/>
    </inertial>
    <visual>
      <origin xyz="0 0 0" rpy="0 0 0"/>
      <geometry>
        <mesh filename="package://oryxbot_description/meshes/arm/link_5.STL"/>
      </geometry>
      <!-- material name="White"/-->
    </visual>
    <collision>
      <origin xyz="0 0 0" rpy="0 0 0"/>
      <geometry>
        <mesh filename="package://oryxbot_description/meshes/arm/link_5.STL"/>
      </geometry>
    </collision>
  </link>
  <joint name="joint_6" type="revolute">
    <origin xyz="0.07431 -0.12684 0.0" rpy="0 3.14159265 0"/>
    <parent link="link_5"/>
    <child link="link_6"/>
    <axis xyz="0 0 1"/>
    <limit effort="150.0" lower="-3.14159265" upper="3.14159265" velocity="3.15"/>
  </joint>
  <link name="link_6">
    <inertial>
      <origin xyz="0 0 0" rpy="0 0 0"/>
      <mass value="0.1"/>
      <inertia ixx="1" ixy="0" ixz="0" iyy="1" iyz="0" izz="1"/>
    </inertial>
    <visual>
      <origin xyz="0 0 0" rpy="0 0 0"/>
      <geometry>
        <mesh filename="package://oryxbot_description/meshes/arm/link_6.STL"/>
      </geometry>
      <material name="Grey"/>
    </visual>
    <collision>
      <origin xyz="0 0 0" rpy="0 0 0"/>
      <geometry>
        <mesh filename="package://oryxbot_description/meshes/arm/link_6.STL"/>
      </geometry>
    </collision>
  </link>
  <!-- Grasping frame -->
  <joint name="tool_joint" type="revolute">
    <parent link="link_6"/>
    <child link="tool_link"/>
    <origin xyz="0 0 0" rpy="1.57079632 0 0"/>
    <limit lower="-3.14159" upper="3.14159" effort="0.1" velocity="0.005"/>
    <axis xyz="0 0 1"/>
  </joint>
  <link name="tool_link">
    <inertial>
      <origin xyz="0 0 0" rpy="0 0 0"/>
      <mass value="0.1"/>
      <inertia ixx="1" ixy="0" ixz="0" iyy="1" iyz="0" izz="1"/>
    </inertial>
    <visual>
      <origin xyz="0 0 0.015" rpy="0 0 0"/>
      <geometry>
        <cylinder radius="0.01" length="0.015"/>
      </geometry>
    </visual>
    <collision>
      <origin xyz="0 0 0.015" rpy="0 0 0"/>
      <geometry>
        <cylinder radius="0.0175" length="0.015"/>
      </geometry>
    </collision>
  </link>
  <gazebo reference="base_link">
    <material>Gazebo/Grey</material>
  </gazebo>
  <gazebo reference="link_1">
    <material>Gazebo/Black</material>
  </gazebo>
  <gazebo reference="link_2">
    <material>Gazebo/Grey</material>
  </gazebo>
  <gazebo reference="link_5">
    <material>Gazebo/Red</material>
  </gazebo>
  <gazebo reference="link_6">
    <material>Gazebo/Black</material>
  </gazebo>
  <gazebo reference="tool_link">
    <material>Gazebo/Grey</material>
  </gazebo>
  <!-- Transmissions for ROS Control -->
  <transmission name="joint_1_trans">
    <type>transmission_interface/SimpleTransmission</type>
    <joint name="joint_1">
      <hardwareInterface>hardware_interface/PositionJointInterface</hardwareInterface>
    </joint>
    <actuator name="joint_1_motor">
      <hardwareInterface>hardware_interface/PositionJointInterface</hardwareInterface>
      <mechanicalReduction>1</mechanicalReduction>
    </actuator>
  </transmission>
  <transmission name="joint_2_trans">
    <type>transmission_interface/SimpleTransmission</type>
    <joint name="joint_2">
      <hardwareInterface>hardware_interface/PositionJointInterface</hardwareInterface>
    </joint>
    <actuator name="joint_2_motor">
      <hardwareInterface>hardware_interface/PositionJointInterface</hardwareInterface>
      <mechanicalReduction>1</mechanicalReduction>
    </actuator>
  </transmission>
  <transmission name="joint_5_trans">
    <type>transmission_interface/SimpleTransmission</type>
    <joint name="joint_5">
      <hardwareInterface>hardware_interface/PositionJointInterface</hardwareInterface>
    </joint>
    <actuator name="joint_5_motor">
      <hardwareInterface>hardware_interface/PositionJointInterface</hardwareInterface>
      <mechanicalReduction>1</mechanicalReduction>
    </actuator>
  </transmission>
  <transmission name="joint_6_trans">
    <type>transmission_interface/SimpleTransmission</type>
    <joint name="joint_6">
      <hardwareInterface>hardware_interface/PositionJointInterface</hardwareInterface>
    </joint>
    <actuator name="joint_6_motor">
      <hardwareInterface>hardware_interface/PositionJointInterface</hardwareInterface>
      <mechanicalReduction>1</mechanicalReduction>
    </actuator>
  </transmission>
  <transmission name="tool_joint_trans">
    <type>transmission_interface/SimpleTransmission</type>
    <joint name="tool_joint">
      <hardwareInterface>hardware_interface/PositionJointInterface</hardwareInterface>
    </joint>
    <actuator name="tool_joint_motor">
      <hardwareInterface>hardware_interface/PositionJointInterface</hardwareInterface>
      <mechanicalReduction>1</mechanicalReduction>
    </actuator>
  </transmission>
  <gazebo>
    <plugin name="gazebo_ros_control" filename="libgazebo_ros_control.so">
      <robotNamespace>/oryxbot_arm</robotNamespace>
    </plugin>
  </gazebo>
</robot>
